<?xml version="1.0" encoding="UTF-8"?>
<testng-results skipped="0" failed="1" ignored="0" total="2" passed="1">
  <reporter-output>
  </reporter-output>
  <suite name="Suite" duration-ms="50" started-at="2018-03-02T09:10:14Z" finished-at="2018-03-02T09:10:14Z">
    <groups>
    </groups>
    <test name="Test" duration-ms="50" started-at="2018-03-02T09:10:14Z" finished-at="2018-03-02T09:10:14Z">
      <class name="test.test">
        <test-method status="FAIL" signature="Dummy_test_to_fail()[pri:0, instance:test.test@17f6480]" name="Dummy_test_to_fail" duration-ms="11" started-at="2018-03-02T11:10:14Z" finished-at="2018-03-02T11:10:14Z">
          <exception class="java.lang.AssertionError">
            <message>
              <![CDATA[expected [1] but found [2]]]>
            </message>
            <full-stacktrace>
              <![CDATA[java.lang.AssertionError: expected [1] but found [2]
	at org.testng.Assert.fail(Assert.java:93)
	at org.testng.Assert.failNotEquals(Assert.java:512)
	at org.testng.Assert.assertEqualsImpl(Assert.java:134)
	at org.testng.Assert.assertEquals(Assert.java:115)
	at org.testng.Assert.assertEquals(Assert.java:388)
	at org.testng.Assert.assertEquals(Assert.java:398)
	at test.test.Dummy_test_to_fail(test.java:15)
	at sun.reflect.NativeMethodAccessorImpl.invoke0(Native Method)
	at sun.reflect.NativeMethodAccessorImpl.invoke(Unknown Source)
	at sun.reflect.DelegatingMethodAccessorImpl.invoke(Unknown Source)
	at java.lang.reflect.Method.invoke(Unknown Source)
	at org.testng.internal.MethodInvocationHelper.invokeMethod(MethodInvocationHelper.java:108)
	at org.testng.internal.Invoker.invokeMethod(Invoker.java:661)
	at org.testng.internal.Invoker.invokeTestMethod(Invoker.java:869)
	at org.testng.internal.Invoker.invokeTestMethods(Invoker.java:1193)
	at org.testng.internal.TestMethodWorker.invokeTestMethods(TestMethodWorker.java:126)
	at org.testng.internal.TestMethodWorker.run(TestMethodWorker.java:109)
	at org.testng.TestRunner.privateRun(TestRunner.java:744)
	at org.testng.TestRunner.run(TestRunner.java:602)
	at org.testng.SuiteRunner.runTest(SuiteRunner.java:380)
	at org.testng.SuiteRunner.runSequentially(SuiteRunner.java:375)
	at org.testng.SuiteRunner.privateRun(SuiteRunner.java:340)
	at org.testng.SuiteRunner.run(SuiteRunner.java:289)
	at org.testng.SuiteRunnerWorker.runSuite(SuiteRunnerWorker.java:52)
	at org.testng.SuiteRunnerWorker.run(SuiteRunnerWorker.java:86)
	at org.testng.TestNG.runSuitesSequentially(TestNG.java:1301)
	at org.testng.TestNG.runSuitesLocally(TestNG.java:1226)
	at org.testng.TestNG.runSuites(TestNG.java:1144)
	at org.testng.TestNG.run(TestNG.java:1115)
	at org.apache.maven.surefire.testng.TestNGExecutor.run(TestNGExecutor.java:281)
	at org.apache.maven.surefire.testng.TestNGXmlTestSuite.execute(TestNGXmlTestSuite.java:75)
	at org.apache.maven.surefire.testng.TestNGProvider.invoke(TestNGProvider.java:121)
	at org.apache.maven.surefire.booter.ForkedBooter.invokeProviderInSameClassLoader(ForkedBooter.java:290)
	at org.apache.maven.surefire.booter.ForkedBooter.runSuitesInProcess(ForkedBooter.java:242)
	at org.apache.maven.surefire.booter.ForkedBooter.main(ForkedBooter.java:121)
]]>
            </full-stacktrace>
          </exception> <!-- java.lang.AssertionError -->
          <reporter-output>
          </reporter-output>
        </test-method> <!-- Dummy_test_to_fail -->
        <test-method status="PASS" signature="Dummy_test_to_pass()[pri:0, instance:test.test@17f6480]" name="Dummy_test_to_pass" duration-ms="0" started-at="2018-03-02T11:10:14Z" finished-at="2018-03-02T11:10:14Z">
          <reporter-output>
          </reporter-output>
        </test-method> <!-- Dummy_test_to_pass -->
      </class> <!-- test.test -->
    </test> <!-- Test -->
  </suite> <!-- Suite -->
</testng-results>
